Workbook

Sheet aw_data
A1: Student_ID | B1: Name | C1: Dept | D1: CGPA | E1: Skills | F1: Internship | G1: Company | H1: Package_LPA | I1: placement_status
A2: 1007 | B2: Aditya | C2: CIVIL | D2: 6.9 | E2: AutoCAD | F2: No | H2: 0 | I2: =IF(H2=0, "NOT_PLACED","PLACED") -> NOT_PLACED
A3: 1059 | B3: Ayaan | C3: CIVIL | D3: 6.8 | E3: AutoCAD | F3: No | H3: 0 | I3: =IF(H3=0, "NOT_PLACED","PLACED") -> NOT_PLACED
A4: 1035 | B4: Ayush | C4: CIVIL | D4: 6.6 | E4: AutoCAD | F4: No | H4: 0 | I4: =IF(H4=0, "NOT_PLACED","PLACED") -> NOT_PLACED
A5: 1017 | B5: Dev | C5: CIVIL | D5: 6.7 | E5: AutoCAD | F5: No | H5: 0 | I5: =IF(H5=0, "NOT_PLACED","PLACED") -> NOT_PLACED
A6: 1079 | B6: Devansh | C6: CIVIL | D6: 6.7 | E6: AutoCAD | F6: No | H6: 0 | I6: =IF(H6=0, "NOT_PLACED","PLACED") -> NOT_PLACED
A7: 1096 | B7: Kiaan | C7: CIVIL | D7: 6.6 | E7: AutoCAD | F7: No | H7: 0 | I7: =IF(H7=0, "NOT_PLACED","PLACED") -> NOT_PLACED
A8: 1088 | B8: Laksh | C8: CIVIL | D8: 6.8 | E8: AutoCAD | F8: No | H8: 0 | I8: =IF(H8=0, "NOT_PLACED","PLACED") -> NOT_PLACED
A9: 1047 | B9: Om | C9: CIVIL | D9: 6.5 | E9: AutoCAD | F9: No | H9: 0 | I9: =IF(H9=0, "NOT_PLACED","PLACED") -> NOT_PLACED
A10: 1108 | B10: Ritesh | C10: CIVIL | D10: 6.5 | E10: AutoCAD | F10: No | H10: 0 | I10: =IF(H10=0, "NOT_PLACED","PLACED") -> NOT_PLACED
A11: 1069 | B11: Varun | C11: CIVIL | D11: 6.5 | E11: AutoCAD | F11: No | H11: 0 | I11: =IF(H11=0, "NOT_PLACED","PLACED") -> NOT_PLACED
A12: 1120 | B12: Viraj | C12: CIVIL | D12: 6.6 | E12: AutoCAD | F12: No | H12: 0 | I12: =IF(H12=0, "NOT_PLACED","PLACED") -> NOT_PLACED
A13: 1001 | B13: Aarav | C13: CSE | D13: 8.7 | E13: Python | F13: Yes | G13: TCS | H13: 7.2 | I13: =IF(H13=0, "NOT_PLACED","PLACED") -> PLACED
A14: 1048 | B14: Aarohi | C14: CSE | D14: 8.6 | E14: Machine Learning | F14: Yes | G14: Amazon | H14: 21 | I14: =IF(H14=0, "NOT_PLACED","PLACED") -> PLACED
A15: 1085 | B15: Aashi | C15: CSE | D15: 9.3 | E15: Python | F15: Yes | G15: Google | H15: 27 | I15: =IF(H15=0, "NOT_PLACED","PLACED") -> PLACED
A16: 1106 | B16: Advaith | C16: CSE | D16: 7.9 | E16: Java | F16: Yes | G16: TCS | H16: 6 | I16: =IF(H16=0, "NOT_PLACED","PLACED") -> PLACED
A17: 1100 | B17: Advik | C17: CSE | D17: 7.7 | E17: Python | F17: Yes | G17: Infosys | H17: 6.2 | I17: =IF(H17=0, "NOT_PLACED","PLACED") -> PLACED
A18: 1097 | B18: Anaira | C18: CSE | D18: 8.8 | E18: Machine Learning | F18: Yes | G18: Google | H18: 25 | I18: =IF(H18=0, "NOT_PLACED","PLACED") -> PLACED
A19: 1004 | B19: Anaya | C19: CSE | D19: 9.1 | E19: Python | F19: Yes | G19: Google | H19: 24 | I19: =IF(H19=0, "NOT_PLACED","PLACED") -> PLACED
A20: 1115 | B20: Anvi | C20: CSE | D20: 9.2 | E20: Machine Learning | F20: Yes | G20: Amazon | H20: 24 | I20: =IF(H20=0, "NOT_PLACED","PLACED") -> PLACED
A21: 1011 | B21: Arjun | C21: CSE | D21: 7.8 | E21: Java | F21: Yes | G21: Infosys | H21: 6.2 | I21: =IF(H21=0, "NOT_PLACED","PLACED") -> PLACED
A22: 1070 | B22: Charvi | C22: CSE | D22: 8.8 | E22: Python | F22: Yes | G22: Google | H22: 22 | I22: =IF(H22=0, "NOT_PLACED","PLACED") -> PLACED
A23: 1033 | B23: Daksh | C23: CSE | D23: 7.9 | E23: Python | F23: Yes | G23: Wipro | H23: 5.7 | I23: =IF(H23=0, "NOT_PLACED","PLACED") -> PLACED
A24: 1076 | B24: Ishani | C24: CSE | D24: 9.2 | E24: Machine Learning | F24: Yes | G24: Microsoft | H24: 31 | I24: =IF(H24=0, "NOT_PLACED","PLACED") -> PLACED
... A41: 1060 | B41: Samaira | C41: CSE | D41: 8.7 | E41: Machine Learning | F41: Yes | G41: Microsoft | H41: 29 | I41: =IF(H41=0, "NOT_PLACED","PLACED") -> PLACED
A42: 1051 | B42: Samar | C42: CSE | D42: 7.2 | E42: SQL | F42: No | H42: 0 | I42: =IF(H42=0, "NOT_PLACED","PLACED") -> NOT_PLACED
A43: 1036 | B43: Siya | C43: CSE | D43: 8.9 | E43: SQL | F43: Yes | G43: Amazon | H43: 20 | I43: =IF(H43=0, "NOT_PLACED","PLACED") -> PLACED
A44: 1024 | B44: Tara | C44: CSE | D44: 9 | E44: Machine Learning | F44: Yes | G44: Google | H44: 25 | I44: =IF(H44=0, "NOT_PLACED","PLACED") -> PLACED
A45: 1118 | B45: Tejas | C45: CSE | D45: 7.8 | E45: SQL | F45: Yes | G45: TCS | H45: 6.3 | I45: =IF(H45=0, "NOT_PLACED","PLACED") -> PLACED
A46: 1093 | B46: Vanya | C46: CSE | D46: 9.1 | E46: Python | F46: Yes | G46: Amazon | H46: 24 | I46: =IF(H46=0, "NOT_PLACED","PLACED") -> PLACED
A47: 1027 | B47: Veer | C47: CSE | D47: 7.5 | E47: Java | F47: Yes | G47: Capgemini | H47: 6.1 | I47: =IF(H47=0, "NOT_PLACED","PLACED") -> PLACED
A48: 1103 | B48: Yamini | C48: CSE | D48: 9 | E48: Machine Learning | F48: Yes | G48: Microsoft | H48: 30 | I48: =IF(H48=0, "NOT_PLACED","PLACED") -> PLACED
A49: 1112 | B49: Yug | C49: CSE | D49: 7.6 | E49: Python | F49: Yes | G49: Wipro | H49: 5.6 | I49: =IF(H49=0, "NOT_PLACED","PLACED") -> PLACED
A50: 1080 | B50: Zoya | C50: CSE | D50: 8.9 | E50: Machine Learning | F50: Yes | G50: Amazon | H50: 23 | I50: =IF(H50=0, "NOT_PLACED","PLACED") -> PLACED
A51: 1012 | B51: Aadhya | C51: ECE | D51: 8.3 | E51: Embedded C | F51: Yes | G51: Capgemini | H51: 7 | I51: =IF(H51=0, "NOT_PLACED","PLACED") -> PLACED
A52: 1111 | B52: Aarna | C52: ECE | D52: 8.1 | E52: Embedded C | F52: Yes | G52: Capgemini | H52: 7.2 | I52: =IF(H52=0, "NOT_PLACED","PLACED") -> PLACED
A53: 1041 | B53: Abeer | C53: ECE | D53: 7 | E53: Embedded C | F53: No | H53: 0 | I53: =IF(H53=0, "NOT_PLACED","PLACED") -> NOT_PLACED
A54: 1074 | B54: Ahana | C54: ECE | D54: 8.3 | E54: Power BI | F54: Yes | G54: Deloitte | H54: 9.6 | I54: =IF(H54=0, "NOT_PLACED","PLACED") -> PLACED
A55: 1068 | B55: Angel | C55: ECE | D55: 8.1 | E55: Embedded C | F55: Yes | G55: Capgemini | H55: 7.1 | I55: =IF(H55=0, "NOT_PLACED","PLACED") -> PLACED
A56: 1016 | B56: Anika | C56: ECE | D56: 8.1 | E56: Python | F56: Yes | G56: Tech Mahindra | H56: 6.4 | I56: =IF(H56=0, "NOT_PLACED","PLACED") -> PLACED
...

Sheet student_count

Sheet Dashboard
A1: PLACEMENT ANALYTICS DASHBOARD 📝
A4: TOTAL STUDENTS👩🏻‍🎓 | D4: PLACEMENT % 📈 | G4: AVERAGE PACKAGE💲 | J4: HIGHEST (LPA)💵 | M4: NOT PLACED🙋🏼‍♂️
A5: =COUNTA(aw_data!A2:A121) -> 120 | D5: =COUNTIF(aw_data!I2:I121,"Placed")/COUNTA(aw_data!A2:A121) -> 0.75 | G5: =AVERAGE(aw_data!H2:H121) -> 8.7041667 | J5: =MAX(aw_data!H2:H121) -> 31 | M5: =COUNTIF(aw_data!I2:I121,"NOT_PLACED") -> 30

Sheet Detail3-MECH
A1: Student_ID | B1: Name | C1: Dept | D1: CGPA | E1: Skills | F1: Internship | G1: Company | H1: Package_LPA | I1: placement_status
A2: 1005 | B2: Ishaan | C2: MECH | D2: 7.2 | E2: Excel | F2: No | H2: 0 | I2: NOT_PLACED
A3: 1025 | B3: Reyansh | C3: MECH | D3: 7 | E3: AutoCAD | F3: No | H3: 0 | I3: NOT_PLACED

Sheet Detail2-CSE
A1: Student_ID | B1: Name | C1: Dept | D1: CGPA | E1: Skills | F1: Internship | G1: Company | H1: Package_LPA | I1: placement_status
A2: 1001 | B2: Aarav | C2: CSE | D2: 8.7 | E2: Python | F2: Yes | G2: TCS | H2: 7.2 | I2: PLACED
A3: 1048 | B3: Aarohi | C3: CSE | D3: 8.6 | E3: Machine Learning | F3: Yes | G3: Amazon | H3: 21 | I3: PLACED
A4: 1085 | B4: Aashi | C4: CSE | D4: 9.3 | E4: Python | F4: Yes | G4: Google | H4: 27 | I4: PLACED
A5: 1106 | B5: Advaith | C5: CSE | D5: 7.9 | E5: Java | F5: Yes | G5: TCS | H5: 6 | I5: PLACED
A6: 1100 | B6: Advik | C6: CSE | D6: 7.7 | E6: Python | F6: Yes | G6: Infosys | H6: 6.2 | I6: PLACED
A7: 1097 | B7: Anaira | C7: CSE | D7: 8.8 | E7: Machine Learning | F7: Yes | G7: Google | H7: 25 | I7: PLACED
A8: 1004 | B8: Anaya | C8: CSE | D8: 9.1 | E8: Python | F8: Yes | G8: Google | H8: 24 | I8: PLACED
A9: 1115 | B9: Anvi | C9: CSE | D9: 9.2 | E9: Machine Learning | F9: Yes | G9: Amazon | H9: 24 | I9: PLACED
A10: 1011 | B10: Arjun | C10: CSE | D10: 7.8 | E10: Java | F10: Yes | G10: Infosys | H10: 6.2 | I10: PLACED
A11: 1070 | B11: Charvi | C11: CSE | D11: 8.8 | E11: Python | F11: Yes | G11: Google | H11: 22 | I11: PLACED
A12: 1033 | B12: Daksh | C12: CSE | D12: 7.9 | E12: Python | F12: Yes | G12: Wipro | H12: 5.7 | I12: PLACED
A13: 1076 | B13: Ishani | C13: CSE | D13: 9.2 | E13: Machine Learning | F13: Yes | G13: Microsoft | H13: 31 | I13: PLACED
... A30: 1060 | B30: Samaira | C30: CSE | D30: 8.7 | E30: Machine Learning | F30: Yes | G30: Microsoft | H30: 29 | I30: PLACED
A31: 1051 | B31: Samar | C31: CSE | D31: 7.2 | E31: SQL | F31: No | H31: 0 | I31: NOT_PLACED
A32: 1036 | B32: Siya | C32: CSE | D32: 8.9 | E32: SQL | F32: Yes | G32: Amazon | H32: 20 | I32: PLACED
A33: 1024 | B33: Tara | C33: CSE | D33: 9 | E33: Machine Learning | F33: Yes | G33: Google | H33: 25 | I33: PLACED
A34: 1118 | B34: Tejas | C34: CSE | D34: 7.8 | E34: SQL | F34: Yes | G34: TCS | H34: 6.3 | I34: PLACED
A35: 1093 | B35: Vanya | C35: CSE | D35: 9.1 | E35: Python | F35: Yes | G35: Amazon | H35: 24 | I35: PLACED
A36: 1027 | B36: Veer | C36: CSE | D36: 7.5 | E36: Java | F36: Yes | G36: Capgemini | H36: 6.1 | I36: PLACED
A37: 1103 | B37: Yamini | C37: CSE | D37: 9 | E37: Machine Learning | F37: Yes | G37: Microsoft | H37: 30 | I37: PLACED
A38: 1112 | B38: Yug | C38: CSE | D38: 7.6 | E38: Python | F38: Yes | G38: Wipro | H38: 5.6 | I38: PLACED
A39: 1080 | B39: Zoya | C39: CSE | D39: 8.9 | E39: Machine Learning | F39: Yes | G39: Amazon | H39: 23 | I39: PLACED
H40: =AVERAGE(H2:H39) -> 16.684211

Sheet Detail1-ECE
A1: Student_ID | B1: Name | C1: Dept | D1: CGPA | E1: Skills | F1: Internship | G1: Company | H1: Package_LPA | I1: placement_status
A2: 1012 | B2: Aadhya | C2: ECE | D2: 8.3 | E2: Embedded C | F2: Yes | G2: Capgemini | H2: 7 | I2: PLACED
A3: 1111 | B3: Aarna | C3: ECE | D3: 8.1 | E3: Embedded C | F3: Yes | G3: Capgemini | H3: 7.2 | I3: PLACED
A4: 1041 | B4: Abeer | C4: ECE | D4: 7 | E4: Embedded C | F4: No | H4: 0 | I4: NOT_PLACED
A5: 1074 | B5: Ahana | C5: ECE | D5: 8.3 | E5: Power BI | F5: Yes | G5: Deloitte | H5: 9.6 | I5: PLACED
A6: 1068 | B6: Angel | C6: ECE | D6: 8.1 | E6: Embedded C | F6: Yes | G6: Capgemini | H6: 7.1 | I6: PLACED
A7: 1016 | B7: Anika | C7: ECE | D7: 8.1 | E7: Python | F7: Yes | G7: Tech Mahindra | H7: 6.4 | I7: PLACED
A8: 1038 | B8: Anvi | C8: ECE | D8: 8.2 | E8: Power BI | F8: Yes | G8: Deloitte | H8: 9.1 | I8: PLACED
A9: 1053 | B9: Arnav | C9: ECE | D9: 7.5 | E9: Java | F9: Yes | G9: Infosys | H9: 5.8 | I9: PLACED
A10: 1029 | B10: Atharv | C10: ECE | D10: 7.2 | E10: SQL | F10: No | G10: TCS | H10: 4.3 | I10: PLACED
A11: 1002 | B11: Diya | C11: ECE | D11: 7.9 | E11: SQL | F11: Yes | G11: Infosys | H11: 5.5 | I11: PLACED
A12: 1083 | B12: Inaaya | C12: ECE | D12: 8 | E12: Power BI | F12: Yes | G12: Deloitte | H12: 9.2 | I12: PLACED
A13: 1022 | B13: Ira | C13: ECE | D13: 7.7 | E13: Embedded C | F13: Yes | G13: Infosys | H13: 5.9 | I13: PLACED
A14: 1119 | B14: Kashvi | C14: ECE | D14: 8.5 | E14: Power BI | F14: Yes | G14: Deloitte | H14: 9.5 | I14: PLACED
A15: 1034 | B15: Kavya | C15: ECE | D15: 8.5 | E15: Embedded C | F15: Yes | G15: Infosys | H15: 6.6 | I15: PLACED
A16: 1061 | B16: Krish | C16: ECE | D16: 7.3 | E16: Embedded C | F16: No | G16: Wipro | H16: 4.7 | I16: PLACED
... A22: 1046 | B22: Pihu | C22: ECE | D22: 8.3 | E22: Power BI | F22: Yes | G22: Capgemini | H22: 7.2 | I22: PLACED
A23: 1114 | B23: Rohan | C23: ECE | D23: 7.2 | E23: Java | F23: No | H23: 0 | I23: NOT_PLACED
A24: 1102 | B24: Rudransh | C24: ECE | D24: 7.1 | E24: Embedded C | F24: No | H24: 0 | I24: NOT_PLACED
A25: 1050 | B25: Ruhi | C25: ECE | D25: 8.1 | E25: Embedded C | F25: Yes | G25: Wipro | H25: 5.9 | I25: PLACED
A26: 1091 | B26: Saanika | C26: ECE | D26: 8.5 | E26: Power BI | F26: Yes | G26: Deloitte | H26: 9.7 | I26: PLACED
A27: 1006 | B27: Saanvi | C27: ECE | D27: 8 | E27: Power BI | F27: Yes | G27: Wipro | H27: 6.1 | I27: PLACED
A28: 1099 | B28: Saisha | C28: ECE | D28: 8.3 | E28: Power BI | F28: Yes | G28: Deloitte | H28: 9.3 | I28: PLACED
A29: 1058 | B29: Shanaya | C29: ECE | D29: 8 | E29: Power BI | F29: Yes | G29: TCS | H29: 6.8 | I29: PLACED
A30: 1071 | B30: Shivam | C30: ECE | D30: 7.2 | E30: Java | F30: No | H30: 0 | I30: NOT_PLACED
A31: 1107 | B31: Sia | C31: ECE | D31: 8.4 | E31: Power BI | F31: Yes | G31: Deloitte | H31: 9.8 | I31: PLACED
A32: 1095 | B32: Tanya | C32: ECE | D32: 8.1 | E32: Embedded C | F32: Yes | G32: TCS | H32: 6.6 | I32: PLACED
A33: 1019 | B33: Yash | C33: ECE | D33: 7.4 | E33: Java | F33: No | G33: Wipro | H33: 4.8 | I33: PLACED
